2025-10-14 16:56:13,744 - app - ERROR - Exception on /login [POST]
Traceback (most recent call last):
  File "/home/antonio/Desktop/egc_p2_1/uvlhub/venv/lib/python3.12/site-packages/sqlalchemy/engine/base.py", line 143, in __init__
    self._dbapi_connection = engine.raw_connection()
                             ^^^^^^^^^^^^^^^^^^^^^^^
  File "/home/antonio/Desktop/egc_p2_1/uvlhub/venv/lib/python3.12/site-packages/sqlalchemy/engine/base.py", line 3295, in raw_connection
    return self.pool.connect()
           ^^^^^^^^^^^^^^^^^^^
  File "/home/antonio/Desktop/egc_p2_1/uvlhub/venv/lib/python3.12/site-packages/sqlalchemy/pool/base.py", line 447, in connect
    return _ConnectionFairy._checkout(self)
           ^^^^^^^^^^^^^^^^^^^^^^^^^^^^^^^^
  File "/home/antonio/Desktop/egc_p2_1/uvlhub/venv/lib/python3.12/site-packages/sqlalchemy/pool/base.py", line 1264, in _checkout
    fairy = _ConnectionRecord.checkout(pool)
            ^^^^^^^^^^^^^^^^^^^^^^^^^^^^^^^^
  File "/home/antonio/Desktop/egc_p2_1/uvlhub/venv/lib/python3.12/site-packages/sqlalchemy/pool/base.py", line 711, in checkout
    rec = pool._do_get()
          ^^^^^^^^^^^^^^
  File "/home/antonio/Desktop/egc_p2_1/uvlhub/venv/lib/python3.12/site-packages/sqlalchemy/pool/impl.py", line 177, in _do_get
    with util.safe_reraise():
         ^^^^^^^^^^^^^^^^^^^
  File "/home/antonio/Desktop/egc_p2_1/uvlhub/venv/lib/python3.12/site-packages/sqlalchemy/util/langhelpers.py", line 224, in __exit__
    raise exc_value.with_traceback(exc_tb)
  File "/home/antonio/Desktop/egc_p2_1/uvlhub/venv/lib/python3.12/site-packages/sqlalchemy/pool/impl.py", line 175, in _do_get
    return self._create_connection()
           ^^^^^^^^^^^^^^^^^^^^^^^^^
  File "/home/antonio/Desktop/egc_p2_1/uvlhub/venv/lib/python3.12/site-packages/sqlalchemy/pool/base.py", line 388, in _create_connection
    return _ConnectionRecord(self)
           ^^^^^^^^^^^^^^^^^^^^^^^
  File "/home/antonio/Desktop/egc_p2_1/uvlhub/venv/lib/python3.12/site-packages/sqlalchemy/pool/base.py", line 673, in __init__
    self.__connect()
  File "/home/antonio/Desktop/egc_p2_1/uvlhub/venv/lib/python3.12/site-packages/sqlalchemy/pool/base.py", line 899, in __connect
    with util.safe_reraise():
         ^^^^^^^^^^^^^^^^^^^
  File "/home/antonio/Desktop/egc_p2_1/uvlhub/venv/lib/python3.12/site-packages/sqlalchemy/util/langhelpers.py", line 224, in __exit__
    raise exc_value.with_traceback(exc_tb)
  File "/home/antonio/Desktop/egc_p2_1/uvlhub/venv/lib/python3.12/site-packages/sqlalchemy/pool/base.py", line 895, in __connect
    self.dbapi_connection = connection = pool._invoke_creator(self)
                                         ^^^^^^^^^^^^^^^^^^^^^^^^^^
  File "/home/antonio/Desktop/egc_p2_1/uvlhub/venv/lib/python3.12/site-packages/sqlalchemy/engine/create.py", line 646, in connect
    return dialect.connect(*cargs, **cparams)
           ^^^^^^^^^^^^^^^^^^^^^^^^^^^^^^^^^^
  File "/home/antonio/Desktop/egc_p2_1/uvlhub/venv/lib/python3.12/site-packages/sqlalchemy/engine/default.py", line 626, in connect
    return self.loaded_dbapi.connect(*cargs, **cparams)  # type: ignore[no-any-return]  # NOQA: E501
           ^^^^^^^^^^^^^^^^^^^^^^^^^^^^^^^^^^^^^^^^^^^^
  File "/home/antonio/Desktop/egc_p2_1/uvlhub/venv/lib/python3.12/site-packages/pymysql/connections.py", line 361, in __init__
    self.connect()
  File "/home/antonio/Desktop/egc_p2_1/uvlhub/venv/lib/python3.12/site-packages/pymysql/connections.py", line 669, in connect
    self._request_authentication()
  File "/home/antonio/Desktop/egc_p2_1/uvlhub/venv/lib/python3.12/site-packages/pymysql/connections.py", line 957, in _request_authentication
    auth_packet = self._read_packet()
                  ^^^^^^^^^^^^^^^^^^^
  File "/home/antonio/Desktop/egc_p2_1/uvlhub/venv/lib/python3.12/site-packages/pymysql/connections.py", line 775, in _read_packet
    packet.raise_for_error()
  File "/home/antonio/Desktop/egc_p2_1/uvlhub/venv/lib/python3.12/site-packages/pymysql/protocol.py", line 219, in raise_for_error
    err.raise_mysql_exception(self._data)
  File "/home/antonio/Desktop/egc_p2_1/uvlhub/venv/lib/python3.12/site-packages/pymysql/err.py", line 150, in raise_mysql_exception
    raise errorclass(errno, errval)
pymysql.err.OperationalError: (1045, "Access denied for user 'default_user'@'localhost' (using password: YES)")

The above exception was the direct cause of the following exception:

Traceback (most recent call last):
  File "/home/antonio/Desktop/egc_p2_1/uvlhub/venv/lib/python3.12/site-packages/flask/app.py", line 1511, in wsgi_app
    response = self.full_dispatch_request()
               ^^^^^^^^^^^^^^^^^^^^^^^^^^^^
  File "/home/antonio/Desktop/egc_p2_1/uvlhub/venv/lib/python3.12/site-packages/flask/app.py", line 919, in full_dispatch_request
    rv = self.handle_user_exception(e)
         ^^^^^^^^^^^^^^^^^^^^^^^^^^^^^
  File "/home/antonio/Desktop/egc_p2_1/uvlhub/venv/lib/python3.12/site-packages/flask_restful/__init__.py", line 298, in error_router
    return original_handler(e)
           ^^^^^^^^^^^^^^^^^^^
  File "/home/antonio/Desktop/egc_p2_1/uvlhub/venv/lib/python3.12/site-packages/flask/app.py", line 917, in full_dispatch_request
    rv = self.dispatch_request()
         ^^^^^^^^^^^^^^^^^^^^^^^
  File "/home/antonio/Desktop/egc_p2_1/uvlhub/venv/lib/python3.12/site-packages/flask/app.py", line 902, in dispatch_request
    return self.ensure_sync(self.view_functions[rule.endpoint])(**view_args)  # type: ignore[no-any-return]
           ^^^^^^^^^^^^^^^^^^^^^^^^^^^^^^^^^^^^^^^^^^^^^^^^^^^^^^^^^^^^^^^^^
  File "/home/antonio/Desktop/egc_p2_1/uvlhub/app/modules/auth/routes.py", line 43, in login
    if authentication_service.login(form.email.data, form.password.data):
       ^^^^^^^^^^^^^^^^^^^^^^^^^^^^^^^^^^^^^^^^^^^^^^^^^^^^^^^^^^^^^^^^^
  File "/home/antonio/Desktop/egc_p2_1/uvlhub/app/modules/auth/services.py", line 19, in login
    user = self.repository.get_by_email(email)
           ^^^^^^^^^^^^^^^^^^^^^^^^^^^^^^^^^^^
  File "/home/antonio/Desktop/egc_p2_1/uvlhub/app/modules/auth/repositories.py", line 21, in get_by_email
    return self.model.query.filter_by(email=email).first()
           ^^^^^^^^^^^^^^^^^^^^^^^^^^^^^^^^^^^^^^^^^^^^^^^
  File "/home/antonio/Desktop/egc_p2_1/uvlhub/venv/lib/python3.12/site-packages/sqlalchemy/orm/query.py", line 2759, in first
    return self.limit(1)._iter().first()  # type: ignore
           ^^^^^^^^^^^^^^^^^^^^^
  File "/home/antonio/Desktop/egc_p2_1/uvlhub/venv/lib/python3.12/site-packages/sqlalchemy/orm/query.py", line 2857, in _iter
    result: Union[ScalarResult[_T], Result[_T]] = self.session.execute(
                                                  ^^^^^^^^^^^^^^^^^^^^^
  File "/home/antonio/Desktop/egc_p2_1/uvlhub/venv/lib/python3.12/site-packages/sqlalchemy/orm/session.py", line 2365, in execute
    return self._execute_internal(
           ^^^^^^^^^^^^^^^^^^^^^^^
  File "/home/antonio/Desktop/egc_p2_1/uvlhub/venv/lib/python3.12/site-packages/sqlalchemy/orm/session.py", line 2241, in _execute_internal
    conn = self._connection_for_bind(bind)
           ^^^^^^^^^^^^^^^^^^^^^^^^^^^^^^^
  File "/home/antonio/Desktop/egc_p2_1/uvlhub/venv/lib/python3.12/site-packages/sqlalchemy/orm/session.py", line 2110, in _connection_for_bind
    return trans._connection_for_bind(engine, execution_options)
           ^^^^^^^^^^^^^^^^^^^^^^^^^^^^^^^^^^^^^^^^^^^^^^^^^^^^^
  File "<string>", line 2, in _connection_for_bind
  File "/home/antonio/Desktop/egc_p2_1/uvlhub/venv/lib/python3.12/site-packages/sqlalchemy/orm/state_changes.py", line 137, in _go
    ret_value = fn(self, *arg, **kw)
                ^^^^^^^^^^^^^^^^^^^^
  File "/home/antonio/Desktop/egc_p2_1/uvlhub/venv/lib/python3.12/site-packages/sqlalchemy/orm/session.py", line 1189, in _connection_for_bind
    conn = bind.connect()
           ^^^^^^^^^^^^^^
  File "/home/antonio/Desktop/egc_p2_1/uvlhub/venv/lib/python3.12/site-packages/sqlalchemy/engine/base.py", line 3271, in connect
    return self._connection_cls(self)
           ^^^^^^^^^^^^^^^^^^^^^^^^^^
  File "/home/antonio/Desktop/egc_p2_1/uvlhub/venv/lib/python3.12/site-packages/sqlalchemy/engine/base.py", line 145, in __init__
    Connection._handle_dbapi_exception_noconnection(
  File "/home/antonio/Desktop/egc_p2_1/uvlhub/venv/lib/python3.12/site-packages/sqlalchemy/engine/base.py", line 2434, in _handle_dbapi_exception_noconnection
    raise sqlalchemy_exception.with_traceback(exc_info[2]) from e
  File "/home/antonio/Desktop/egc_p2_1/uvlhub/venv/lib/python3.12/site-packages/sqlalchemy/engine/base.py", line 143, in __init__
    self._dbapi_connection = engine.raw_connection()
                             ^^^^^^^^^^^^^^^^^^^^^^^
  File "/home/antonio/Desktop/egc_p2_1/uvlhub/venv/lib/python3.12/site-packages/sqlalchemy/engine/base.py", line 3295, in raw_connection
    return self.pool.connect()
           ^^^^^^^^^^^^^^^^^^^
  File "/home/antonio/Desktop/egc_p2_1/uvlhub/venv/lib/python3.12/site-packages/sqlalchemy/pool/base.py", line 447, in connect
    return _ConnectionFairy._checkout(self)
           ^^^^^^^^^^^^^^^^^^^^^^^^^^^^^^^^
  File "/home/antonio/Desktop/egc_p2_1/uvlhub/venv/lib/python3.12/site-packages/sqlalchemy/pool/base.py", line 1264, in _checkout
    fairy = _ConnectionRecord.checkout(pool)
            ^^^^^^^^^^^^^^^^^^^^^^^^^^^^^^^^
  File "/home/antonio/Desktop/egc_p2_1/uvlhub/venv/lib/python3.12/site-packages/sqlalchemy/pool/base.py", line 711, in checkout
    rec = pool._do_get()
          ^^^^^^^^^^^^^^
  File "/home/antonio/Desktop/egc_p2_1/uvlhub/venv/lib/python3.12/site-packages/sqlalchemy/pool/impl.py", line 177, in _do_get
    with util.safe_reraise():
         ^^^^^^^^^^^^^^^^^^^
  File "/home/antonio/Desktop/egc_p2_1/uvlhub/venv/lib/python3.12/site-packages/sqlalchemy/util/langhelpers.py", line 224, in __exit__
    raise exc_value.with_traceback(exc_tb)
  File "/home/antonio/Desktop/egc_p2_1/uvlhub/venv/lib/python3.12/site-packages/sqlalchemy/pool/impl.py", line 175, in _do_get
    return self._create_connection()
           ^^^^^^^^^^^^^^^^^^^^^^^^^
  File "/home/antonio/Desktop/egc_p2_1/uvlhub/venv/lib/python3.12/site-packages/sqlalchemy/pool/base.py", line 388, in _create_connection
    return _ConnectionRecord(self)
           ^^^^^^^^^^^^^^^^^^^^^^^
  File "/home/antonio/Desktop/egc_p2_1/uvlhub/venv/lib/python3.12/site-packages/sqlalchemy/pool/base.py", line 673, in __init__
    self.__connect()
  File "/home/antonio/Desktop/egc_p2_1/uvlhub/venv/lib/python3.12/site-packages/sqlalchemy/pool/base.py", line 899, in __connect
    with util.safe_reraise():
         ^^^^^^^^^^^^^^^^^^^
  File "/home/antonio/Desktop/egc_p2_1/uvlhub/venv/lib/python3.12/site-packages/sqlalchemy/util/langhelpers.py", line 224, in __exit__
    raise exc_value.with_traceback(exc_tb)
  File "/home/antonio/Desktop/egc_p2_1/uvlhub/venv/lib/python3.12/site-packages/sqlalchemy/pool/base.py", line 895, in __connect
    self.dbapi_connection = connection = pool._invoke_creator(self)
                                         ^^^^^^^^^^^^^^^^^^^^^^^^^^
  File "/home/antonio/Desktop/egc_p2_1/uvlhub/venv/lib/python3.12/site-packages/sqlalchemy/engine/create.py", line 646, in connect
    return dialect.connect(*cargs, **cparams)
           ^^^^^^^^^^^^^^^^^^^^^^^^^^^^^^^^^^
  File "/home/antonio/Desktop/egc_p2_1/uvlhub/venv/lib/python3.12/site-packages/sqlalchemy/engine/default.py", line 626, in connect
    return self.loaded_dbapi.connect(*cargs, **cparams)  # type: ignore[no-any-return]  # NOQA: E501
           ^^^^^^^^^^^^^^^^^^^^^^^^^^^^^^^^^^^^^^^^^^^^
  File "/home/antonio/Desktop/egc_p2_1/uvlhub/venv/lib/python3.12/site-packages/pymysql/connections.py", line 361, in __init__
    self.connect()
  File "/home/antonio/Desktop/egc_p2_1/uvlhub/venv/lib/python3.12/site-packages/pymysql/connections.py", line 669, in connect
    self._request_authentication()
  File "/home/antonio/Desktop/egc_p2_1/uvlhub/venv/lib/python3.12/site-packages/pymysql/connections.py", line 957, in _request_authentication
    auth_packet = self._read_packet()
                  ^^^^^^^^^^^^^^^^^^^
  File "/home/antonio/Desktop/egc_p2_1/uvlhub/venv/lib/python3.12/site-packages/pymysql/connections.py", line 775, in _read_packet
    packet.raise_for_error()
  File "/home/antonio/Desktop/egc_p2_1/uvlhub/venv/lib/python3.12/site-packages/pymysql/protocol.py", line 219, in raise_for_error
    err.raise_mysql_exception(self._data)
  File "/home/antonio/Desktop/egc_p2_1/uvlhub/venv/lib/python3.12/site-packages/pymysql/err.py", line 150, in raise_mysql_exception
    raise errorclass(errno, errval)
sqlalchemy.exc.OperationalError: (pymysql.err.OperationalError) (1045, "Access denied for user 'default_user'@'localhost' (using password: YES)")
(Background on this error at: https://sqlalche.me/e/20/e3q8)
